2024-04-28 09:18:13,634 INFO Set uid to user 0 succeeded
2024-04-28 09:18:13,636 INFO RPC interface 'supervisor' initialized
2024-04-28 09:18:13,636 CRIT Server 'unix_http_server' running without any HTTP authentication checking
2024-04-28 09:18:13,636 INFO supervisord started with pid 1
2024-04-28 09:18:14,639 INFO spawned: 'django' with pid 7
2024-04-28 09:18:14,640 INFO spawned: 'memcached' with pid 8
2024-04-28 09:18:14,641 INFO spawned: 'sshd' with pid 9
2024-04-28 09:18:14,642 INFO spawned: 'sshd_logwatch' with pid 10
INFO 2024-04-28 09:18:15,310 sshd_logwatch 10 Starting sshd logwatch (file: /var/log/auth)
2024-04-28 09:18:15,311 CRIT uncaptured python exception, closing channel <POutputDispatcher at 139975319578448 for <Subprocess at 139975321598480 with name sshd_logwatch in state STARTING> (stderr)> (<class 'OSError'>:[Errno 29] Illegal seek [/usr/lib/python3/dist-packages/supervisor/supervisord.py|runforever|218] [/usr/lib/python3/dist-packages/supervisor/dispatchers.py|handle_read_event|276] [/usr/lib/python3/dist-packages/supervisor/dispatchers.py|record_output|210] [/usr/lib/python3/dist-packages/supervisor/dispatchers.py|_log|179] [/usr/lib/python3/dist-packages/supervisor/loggers.py|info|327] [/usr/lib/python3/dist-packages/supervisor/loggers.py|log|345] [/usr/lib/python3/dist-packages/supervisor/loggers.py|emit|227] [/usr/lib/python3/dist-packages/supervisor/loggers.py|doRollover|264])
Traceback (most recent call last):
  File "/usr/local/lib/python3.12/site-packages/django/db/backends/base/base.py", line 275, in ensure_connection
2024-04-28 09:18:15,318 CRIT uncaptured python exception, closing channel <POutputDispatcher at 139975321660752 for <Subprocess at 139975340682896 with name django in state STARTING> (stderr)> (<class 'OSError'>:[Errno 29] Illegal seek [/usr/lib/python3/dist-packages/supervisor/supervisord.py|runforever|218] [/usr/lib/python3/dist-packages/supervisor/dispatchers.py|handle_read_event|276] [/usr/lib/python3/dist-packages/supervisor/dispatchers.py|record_output|210] [/usr/lib/python3/dist-packages/supervisor/dispatchers.py|_log|179] [/usr/lib/python3/dist-packages/supervisor/loggers.py|info|327] [/usr/lib/python3/dist-packages/supervisor/loggers.py|log|345] [/usr/lib/python3/dist-packages/supervisor/loggers.py|emit|227] [/usr/lib/python3/dist-packages/supervisor/loggers.py|doRollover|264])
    self.connect()
  File "/usr/local/lib/python3.12/site-packages/django/utils/asyncio.py", line 26, in inner
    return func(*args, **kwargs)
           ^^^^^^^^^^^^^^^^^^^^^
  File "/usr/local/lib/python3.12/site-packages/django/db/backends/base/base.py", line 256, in connect
2024-04-28 09:18:15,318 CRIT uncaptured python exception, closing channel <POutputDispatcher at 139975321660752 for <Subprocess at 139975340682896 with name django in state STARTING> (stderr)> (<class 'OSError'>:[Errno 29] Illegal seek [/usr/lib/python3/dist-packages/supervisor/supervisord.py|runforever|218] [/usr/lib/python3/dist-packages/supervisor/dispatchers.py|handle_read_event|276] [/usr/lib/python3/dist-packages/supervisor/dispatchers.py|record_output|210] [/usr/lib/python3/dist-packages/supervisor/dispatchers.py|_log|179] [/usr/lib/python3/dist-packages/supervisor/loggers.py|info|327] [/usr/lib/python3/dist-packages/supervisor/loggers.py|log|345] [/usr/lib/python3/dist-packages/supervisor/loggers.py|emit|227] [/usr/lib/python3/dist-packages/supervisor/loggers.py|doRollover|264])
    self.connection = self.get_new_connection(conn_params)
2024-04-28 09:18:15,318 CRIT uncaptured python exception, closing channel <POutputDispatcher at 139975321660752 for <Subprocess at 139975340682896 with name django in state STARTING> (stderr)> (<class 'OSError'>:[Errno 29] Illegal seek [/usr/lib/python3/dist-packages/supervisor/supervisord.py|runforever|218] [/usr/lib/python3/dist-packages/supervisor/dispatchers.py|handle_read_event|276] [/usr/lib/python3/dist-packages/supervisor/dispatchers.py|record_output|210] [/usr/lib/python3/dist-packages/supervisor/dispatchers.py|_log|179] [/usr/lib/python3/dist-packages/supervisor/loggers.py|info|327] [/usr/lib/python3/dist-packages/supervisor/loggers.py|log|345] [/usr/lib/python3/dist-packages/supervisor/loggers.py|emit|227] [/usr/lib/python3/dist-packages/supervisor/loggers.py|doRollover|264])
                      ^^^^^^^^^^^^^^^^^^^^^^^^^^^^^^^^^^^^
  File "/usr/local/lib/python3.12/site-packages/django/utils/asyncio.py", line 26, in inner
    return func(*args, **kwargs)
           ^^^^^^^^^^^^^^^^^^^^^
  File "/usr/local/lib/python3.12/site-packages/django/db/backends/sqlite3/base.py", line 181, in get_new_connection
2024-04-28 09:18:15,318 CRIT uncaptured python exception, closing channel <POutputDispatcher at 139975321660752 for <Subprocess at 139975340682896 with name django in state STARTING> (stderr)> (<class 'OSError'>:[Errno 29] Illegal seek [/usr/lib/python3/dist-packages/supervisor/supervisord.py|runforever|218] [/usr/lib/python3/dist-packages/supervisor/dispatchers.py|handle_read_event|276] [/usr/lib/python3/dist-packages/supervisor/dispatchers.py|record_output|210] [/usr/lib/python3/dist-packages/supervisor/dispatchers.py|_log|179] [/usr/lib/python3/dist-packages/supervisor/loggers.py|info|327] [/usr/lib/python3/dist-packages/supervisor/loggers.py|log|345] [/usr/lib/python3/dist-packages/supervisor/loggers.py|emit|227] [/usr/lib/python3/dist-packages/supervisor/loggers.py|doRollover|264])
    conn = Database.connect(**conn_params)
2024-04-28 09:18:15,318 CRIT uncaptured python exception, closing channel <POutputDispatcher at 139975321660752 for <Subprocess at 139975340682896 with name django in state STARTING> (stderr)> (<class 'OSError'>:[Errno 29] Illegal seek [/usr/lib/python3/dist-packages/supervisor/supervisord.py|runforever|218] [/usr/lib/python3/dist-packages/supervisor/dispatchers.py|handle_read_event|276] [/usr/lib/python3/dist-packages/supervisor/dispatchers.py|record_output|210] [/usr/lib/python3/dist-packages/supervisor/dispatchers.py|_log|179] [/usr/lib/python3/dist-packages/supervisor/loggers.py|info|327] [/usr/lib/python3/dist-packages/supervisor/loggers.py|log|345] [/usr/lib/python3/dist-packages/supervisor/loggers.py|emit|227] [/usr/lib/python3/dist-packages/supervisor/loggers.py|doRollover|264])
           ^^^^^^^^^^^^^^^^^^^^^^^^^^^^^^^
sqlite3.OperationalError: unable to open database file

The above exception was the direct cause of the following exception:

Traceback (most recent call last):
  File "/app/manage.py", line 22, in <module>
    main()
2024-04-28 09:18:15,318 CRIT uncaptured python exception, closing channel <POutputDispatcher at 139975321660752 for <Subprocess at 139975340682896 with name django in state STARTING> (stderr)> (<class 'OSError'>:[Errno 29] Illegal seek [/usr/lib/python3/dist-packages/supervisor/supervisord.py|runforever|218] [/usr/lib/python3/dist-packages/supervisor/dispatchers.py|handle_read_event|276] [/usr/lib/python3/dist-packages/supervisor/dispatchers.py|record_output|210] [/usr/lib/python3/dist-packages/supervisor/dispatchers.py|_log|179] [/usr/lib/python3/dist-packages/supervisor/loggers.py|info|327] [/usr/lib/python3/dist-packages/supervisor/loggers.py|log|345] [/usr/lib/python3/dist-packages/supervisor/loggers.py|emit|227] [/usr/lib/python3/dist-packages/supervisor/loggers.py|doRollover|264])
  File "/app/manage.py", line 18, in main
    execute_from_command_line(sys.argv)
  File "/usr/local/lib/python3.12/site-packages/django/core/management/__init__.py", line 442, in execute_from_command_line
2024-04-28 09:18:15,318 CRIT uncaptured python exception, closing channel <POutputDispatcher at 139975321660752 for <Subprocess at 139975340682896 with name django in state STARTING> (stderr)> (<class 'OSError'>:[Errno 29] Illegal seek [/usr/lib/python3/dist-packages/supervisor/supervisord.py|runforever|218] [/usr/lib/python3/dist-packages/supervisor/dispatchers.py|handle_read_event|276] [/usr/lib/python3/dist-packages/supervisor/dispatchers.py|record_output|210] [/usr/lib/python3/dist-packages/supervisor/dispatchers.py|_log|179] [/usr/lib/python3/dist-packages/supervisor/loggers.py|info|327] [/usr/lib/python3/dist-packages/supervisor/loggers.py|log|345] [/usr/lib/python3/dist-packages/supervisor/loggers.py|emit|227] [/usr/lib/python3/dist-packages/supervisor/loggers.py|doRollover|264])
    utility.execute()
2024-04-28 09:18:15,318 CRIT uncaptured python exception, closing channel <POutputDispatcher at 139975321660752 for <Subprocess at 139975340682896 with name django in state STARTING> (stderr)> (<class 'OSError'>:[Errno 29] Illegal seek [/usr/lib/python3/dist-packages/supervisor/supervisord.py|runforever|218] [/usr/lib/python3/dist-packages/supervisor/dispatchers.py|handle_read_event|276] [/usr/lib/python3/dist-packages/supervisor/dispatchers.py|record_output|210] [/usr/lib/python3/dist-packages/supervisor/dispatchers.py|_log|179] [/usr/lib/python3/dist-packages/supervisor/loggers.py|info|327] [/usr/lib/python3/dist-packages/supervisor/loggers.py|log|345] [/usr/lib/python3/dist-packages/supervisor/loggers.py|emit|227] [/usr/lib/python3/dist-packages/supervisor/loggers.py|doRollover|264])
  File "/usr/local/lib/python3.12/site-packages/django/core/management/__init__.py", line 436, in execute
2024-04-28 09:18:15,318 CRIT uncaptured python exception, closing channel <POutputDispatcher at 139975321660752 for <Subprocess at 139975340682896 with name django in state STARTING> (stderr)> (<class 'OSError'>:[Errno 29] Illegal seek [/usr/lib/python3/dist-packages/supervisor/supervisord.py|runforever|218] [/usr/lib/python3/dist-packages/supervisor/dispatchers.py|handle_read_event|276] [/usr/lib/python3/dist-packages/supervisor/dispatchers.py|record_output|210] [/usr/lib/python3/dist-packages/supervisor/dispatchers.py|_log|179] [/usr/lib/python3/dist-packages/supervisor/loggers.py|info|327] [/usr/lib/python3/dist-packages/supervisor/loggers.py|log|345] [/usr/lib/python3/dist-packages/supervisor/loggers.py|emit|227] [/usr/lib/python3/dist-packages/supervisor/loggers.py|doRollover|264])
    self.fetch_command(subcommand).run_from_argv(self.argv)
2024-04-28 09:18:15,319 CRIT uncaptured python exception, closing channel <POutputDispatcher at 139975321660752 for <Subprocess at 139975340682896 with name django in state STARTING> (stderr)> (<class 'OSError'>:[Errno 29] Illegal seek [/usr/lib/python3/dist-packages/supervisor/supervisord.py|runforever|218] [/usr/lib/python3/dist-packages/supervisor/dispatchers.py|handle_read_event|276] [/usr/lib/python3/dist-packages/supervisor/dispatchers.py|record_output|210] [/usr/lib/python3/dist-packages/supervisor/dispatchers.py|_log|179] [/usr/lib/python3/dist-packages/supervisor/loggers.py|info|327] [/usr/lib/python3/dist-packages/supervisor/loggers.py|log|345] [/usr/lib/python3/dist-packages/supervisor/loggers.py|emit|227] [/usr/lib/python3/dist-packages/supervisor/loggers.py|doRollover|264])
  File "/usr/local/lib/python3.12/site-packages/django/core/management/base.py", line 413, in run_from_argv
2024-04-28 09:18:15,319 CRIT uncaptured python exception, closing channel <POutputDispatcher at 139975321660752 for <Subprocess at 139975340682896 with name django in state STARTING> (stderr)> (<class 'OSError'>:[Errno 29] Illegal seek [/usr/lib/python3/dist-packages/supervisor/supervisord.py|runforever|218] [/usr/lib/python3/dist-packages/supervisor/dispatchers.py|handle_read_event|276] [/usr/lib/python3/dist-packages/supervisor/dispatchers.py|record_output|210] [/usr/lib/python3/dist-packages/supervisor/dispatchers.py|_log|179] [/usr/lib/python3/dist-packages/supervisor/loggers.py|info|327] [/usr/lib/python3/dist-packages/supervisor/loggers.py|log|345] [/usr/lib/python3/dist-packages/supervisor/loggers.py|emit|227] [/usr/lib/python3/dist-packages/supervisor/loggers.py|doRollover|264])
    self.execute(*args, **cmd_options)
2024-04-28 09:18:15,319 CRIT uncaptured python exception, closing channel <POutputDispatcher at 139975321660752 for <Subprocess at 139975340682896 with name django in state STARTING> (stderr)> (<class 'OSError'>:[Errno 29] Illegal seek [/usr/lib/python3/dist-packages/supervisor/supervisord.py|runforever|218] [/usr/lib/python3/dist-packages/supervisor/dispatchers.py|handle_read_event|276] [/usr/lib/python3/dist-packages/supervisor/dispatchers.py|record_output|210] [/usr/lib/python3/dist-packages/supervisor/dispatchers.py|_log|179] [/usr/lib/python3/dist-packages/supervisor/loggers.py|info|327] [/usr/lib/python3/dist-packages/supervisor/loggers.py|log|345] [/usr/lib/python3/dist-packages/supervisor/loggers.py|emit|227] [/usr/lib/python3/dist-packages/supervisor/loggers.py|doRollover|264])
  File "/usr/local/lib/python3.12/site-packages/django/core/management/base.py", line 459, in execute
2024-04-28 09:18:15,319 CRIT uncaptured python exception, closing channel <POutputDispatcher at 139975321660752 for <Subprocess at 139975340682896 with name django in state STARTING> (stderr)> (<class 'OSError'>:[Errno 29] Illegal seek [/usr/lib/python3/dist-packages/supervisor/supervisord.py|runforever|218] [/usr/lib/python3/dist-packages/supervisor/dispatchers.py|handle_read_event|276] [/usr/lib/python3/dist-packages/supervisor/dispatchers.py|record_output|210] [/usr/lib/python3/dist-packages/supervisor/dispatchers.py|_log|179] [/usr/lib/python3/dist-packages/supervisor/loggers.py|info|327] [/usr/lib/python3/dist-packages/supervisor/loggers.py|log|345] [/usr/lib/python3/dist-packages/supervisor/loggers.py|emit|227] [/usr/lib/python3/dist-packages/supervisor/loggers.py|doRollover|264])
    output = self.handle(*args, **options)
2024-04-28 09:18:15,319 CRIT uncaptured python exception, closing channel <POutputDispatcher at 139975321660752 for <Subprocess at 139975340682896 with name django in state STARTING> (stderr)> (<class 'OSError'>:[Errno 29] Illegal seek [/usr/lib/python3/dist-packages/supervisor/supervisord.py|runforever|218] [/usr/lib/python3/dist-packages/supervisor/dispatchers.py|handle_read_event|276] [/usr/lib/python3/dist-packages/supervisor/dispatchers.py|record_output|210] [/usr/lib/python3/dist-packages/supervisor/dispatchers.py|_log|179] [/usr/lib/python3/dist-packages/supervisor/loggers.py|info|327] [/usr/lib/python3/dist-packages/supervisor/loggers.py|log|345] [/usr/lib/python3/dist-packages/supervisor/loggers.py|emit|227] [/usr/lib/python3/dist-packages/supervisor/loggers.py|doRollover|264])
             ^^^^^^^^^^^^^^^^^^^^^^^^^^^^^
  File "/usr/local/lib/python3.12/site-packages/django/core/management/base.py", line 107, in wrapper
2024-04-28 09:18:15,319 CRIT uncaptured python exception, closing channel <POutputDispatcher at 139975321660752 for <Subprocess at 139975340682896 with name django in state STARTING> (stderr)> (<class 'OSError'>:[Errno 29] Illegal seek [/usr/lib/python3/dist-packages/supervisor/supervisord.py|runforever|218] [/usr/lib/python3/dist-packages/supervisor/dispatchers.py|handle_read_event|276] [/usr/lib/python3/dist-packages/supervisor/dispatchers.py|record_output|210] [/usr/lib/python3/dist-packages/supervisor/dispatchers.py|_log|179] [/usr/lib/python3/dist-packages/supervisor/loggers.py|info|327] [/usr/lib/python3/dist-packages/supervisor/loggers.py|log|345] [/usr/lib/python3/dist-packages/supervisor/loggers.py|emit|227] [/usr/lib/python3/dist-packages/supervisor/loggers.py|doRollover|264])
    res = handle_func(*args, **kwargs)
          ^^^^^^^^^^^^^^^^^^^^^^^^^^^^
  File "/usr/local/lib/python3.12/site-packages/django/core/management/commands/migrate.py", line 117, in handle
2024-04-28 09:18:15,319 CRIT uncaptured python exception, closing channel <POutputDispatcher at 139975321660752 for <Subprocess at 139975340682896 with name django in state STARTING> (stderr)> (<class 'OSError'>:[Errno 29] Illegal seek [/usr/lib/python3/dist-packages/supervisor/supervisord.py|runforever|218] [/usr/lib/python3/dist-packages/supervisor/dispatchers.py|handle_read_event|276] [/usr/lib/python3/dist-packages/supervisor/dispatchers.py|record_output|210] [/usr/lib/python3/dist-packages/supervisor/dispatchers.py|_log|179] [/usr/lib/python3/dist-packages/supervisor/loggers.py|info|327] [/usr/lib/python3/dist-packages/supervisor/loggers.py|log|345] [/usr/lib/python3/dist-packages/supervisor/loggers.py|emit|227] [/usr/lib/python3/dist-packages/supervisor/loggers.py|doRollover|264])
    executor = MigrationExecutor(connection, self.migration_progress_callback)
2024-04-28 09:18:15,319 CRIT uncaptured python exception, closing channel <POutputDispatcher at 139975321660752 for <Subprocess at 139975340682896 with name django in state STARTING> (stderr)> (<class 'OSError'>:[Errno 29] Illegal seek [/usr/lib/python3/dist-packages/supervisor/supervisord.py|runforever|218] [/usr/lib/python3/dist-packages/supervisor/dispatchers.py|handle_read_event|276] [/usr/lib/python3/dist-packages/supervisor/dispatchers.py|record_output|210] [/usr/lib/python3/dist-packages/supervisor/dispatchers.py|_log|179] [/usr/lib/python3/dist-packages/supervisor/loggers.py|info|327] [/usr/lib/python3/dist-packages/supervisor/loggers.py|log|345] [/usr/lib/python3/dist-packages/supervisor/loggers.py|emit|227] [/usr/lib/python3/dist-packages/supervisor/loggers.py|doRollover|264])
               ^^^^^^^^^^^^^^^^^^^^^^^^^^^^^^^^^^^^^^^^^^^^^^^^^^^^^^^^^^^^^^^
  File "/usr/local/lib/python3.12/site-packages/django/db/migrations/executor.py", line 18, in __init__
    self.loader = MigrationLoader(self.connection)
2024-04-28 09:18:15,319 CRIT uncaptured python exception, closing channel <POutputDispatcher at 139975321660752 for <Subprocess at 139975340682896 with name django in state STARTING> (stderr)> (<class 'OSError'>:[Errno 29] Illegal seek [/usr/lib/python3/dist-packages/supervisor/supervisord.py|runforever|218] [/usr/lib/python3/dist-packages/supervisor/dispatchers.py|handle_read_event|276] [/usr/lib/python3/dist-packages/supervisor/dispatchers.py|record_output|210] [/usr/lib/python3/dist-packages/supervisor/dispatchers.py|_log|179] [/usr/lib/python3/dist-packages/supervisor/loggers.py|info|327] [/usr/lib/python3/dist-packages/supervisor/loggers.py|log|345] [/usr/lib/python3/dist-packages/supervisor/loggers.py|emit|227] [/usr/lib/python3/dist-packages/supervisor/loggers.py|doRollover|264])
                  ^^^^^^^^^^^^^^^^^^^^^^^^^^^^^^^^
  File "/usr/local/lib/python3.12/site-packages/django/db/migrations/loader.py", line 58, in __init__
    self.build_graph()
  File "/usr/local/lib/python3.12/site-packages/django/db/migrations/loader.py", line 235, in build_graph
2024-04-28 09:18:15,319 CRIT uncaptured python exception, closing channel <POutputDispatcher at 139975321660752 for <Subprocess at 139975340682896 with name django in state STARTING> (stderr)> (<class 'OSError'>:[Errno 29] Illegal seek [/usr/lib/python3/dist-packages/supervisor/supervisord.py|runforever|218] [/usr/lib/python3/dist-packages/supervisor/dispatchers.py|handle_read_event|276] [/usr/lib/python3/dist-packages/supervisor/dispatchers.py|record_output|210] [/usr/lib/python3/dist-packages/supervisor/dispatchers.py|_log|179] [/usr/lib/python3/dist-packages/supervisor/loggers.py|info|327] [/usr/lib/python3/dist-packages/supervisor/loggers.py|log|345] [/usr/lib/python3/dist-packages/supervisor/loggers.py|emit|227] [/usr/lib/python3/dist-packages/supervisor/loggers.py|doRollover|264])
    self.applied_migrations = recorder.applied_migrations()
2024-04-28 09:18:15,319 CRIT uncaptured python exception, closing channel <POutputDispatcher at 139975321660752 for <Subprocess at 139975340682896 with name django in state STARTING> (stderr)> (<class 'OSError'>:[Errno 29] Illegal seek [/usr/lib/python3/dist-packages/supervisor/supervisord.py|runforever|218] [/usr/lib/python3/dist-packages/supervisor/dispatchers.py|handle_read_event|276] [/usr/lib/python3/dist-packages/supervisor/dispatchers.py|record_output|210] [/usr/lib/python3/dist-packages/supervisor/dispatchers.py|_log|179] [/usr/lib/python3/dist-packages/supervisor/loggers.py|info|327] [/usr/lib/python3/dist-packages/supervisor/loggers.py|log|345] [/usr/lib/python3/dist-packages/supervisor/loggers.py|emit|227] [/usr/lib/python3/dist-packages/supervisor/loggers.py|doRollover|264])
                              ^^^^^^^^^^^^^^^^^^^^^^^^^^^^^
  File "/usr/local/lib/python3.12/site-packages/django/db/migrations/recorder.py", line 89, in applied_migrations
    if self.has_table():
2024-04-28 09:18:15,319 CRIT uncaptured python exception, closing channel <POutputDispatcher at 139975321660752 for <Subprocess at 139975340682896 with name django in state STARTING> (stderr)> (<class 'OSError'>:[Errno 29] Illegal seek [/usr/lib/python3/dist-packages/supervisor/supervisord.py|runforever|218] [/usr/lib/python3/dist-packages/supervisor/dispatchers.py|handle_read_event|276] [/usr/lib/python3/dist-packages/supervisor/dispatchers.py|record_output|210] [/usr/lib/python3/dist-packages/supervisor/dispatchers.py|_log|179] [/usr/lib/python3/dist-packages/supervisor/loggers.py|info|327] [/usr/lib/python3/dist-packages/supervisor/loggers.py|log|345] [/usr/lib/python3/dist-packages/supervisor/loggers.py|emit|227] [/usr/lib/python3/dist-packages/supervisor/loggers.py|doRollover|264])
       ^^^^^^^^^^^^^^^^
  File "/usr/local/lib/python3.12/site-packages/django/db/migrations/recorder.py", line 63, in has_table
2024-04-28 09:18:15,320 CRIT uncaptured python exception, closing channel <POutputDispatcher at 139975321660752 for <Subprocess at 139975340682896 with name django in state STARTING> (stderr)> (<class 'OSError'>:[Errno 29] Illegal seek [/usr/lib/python3/dist-packages/supervisor/supervisord.py|runforever|218] [/usr/lib/python3/dist-packages/supervisor/dispatchers.py|handle_read_event|276] [/usr/lib/python3/dist-packages/supervisor/dispatchers.py|record_output|210] [/usr/lib/python3/dist-packages/supervisor/dispatchers.py|_log|179] [/usr/lib/python3/dist-packages/supervisor/loggers.py|info|327] [/usr/lib/python3/dist-packages/supervisor/loggers.py|log|345] [/usr/lib/python3/dist-packages/supervisor/loggers.py|emit|227] [/usr/lib/python3/dist-packages/supervisor/loggers.py|doRollover|264])
    with self.connection.cursor() as cursor:
         ^^^^^^^^^^^^^^^^^^^^^^^^
  File "/usr/local/lib/python3.12/site-packages/django/utils/asyncio.py", line 26, in inner
    return func(*args, **kwargs)
2024-04-28 09:18:15,320 CRIT uncaptured python exception, closing channel <POutputDispatcher at 139975321660752 for <Subprocess at 139975340682896 with name django in state STARTING> (stderr)> (<class 'OSError'>:[Errno 29] Illegal seek [/usr/lib/python3/dist-packages/supervisor/supervisord.py|runforever|218] [/usr/lib/python3/dist-packages/supervisor/dispatchers.py|handle_read_event|276] [/usr/lib/python3/dist-packages/supervisor/dispatchers.py|record_output|210] [/usr/lib/python3/dist-packages/supervisor/dispatchers.py|_log|179] [/usr/lib/python3/dist-packages/supervisor/loggers.py|info|327] [/usr/lib/python3/dist-packages/supervisor/loggers.py|log|345] [/usr/lib/python3/dist-packages/supervisor/loggers.py|emit|227] [/usr/lib/python3/dist-packages/supervisor/loggers.py|doRollover|264])
           ^^^^^^^^^^^^^^^^^^^^^
  File "/usr/local/lib/python3.12/site-packages/django/db/backends/base/base.py", line 316, in cursor
2024-04-28 09:18:15,320 CRIT uncaptured python exception, closing channel <POutputDispatcher at 139975321660752 for <Subprocess at 139975340682896 with name django in state STARTING> (stderr)> (<class 'OSError'>:[Errno 29] Illegal seek [/usr/lib/python3/dist-packages/supervisor/supervisord.py|runforever|218] [/usr/lib/python3/dist-packages/supervisor/dispatchers.py|handle_read_event|276] [/usr/lib/python3/dist-packages/supervisor/dispatchers.py|record_output|210] [/usr/lib/python3/dist-packages/supervisor/dispatchers.py|_log|179] [/usr/lib/python3/dist-packages/supervisor/loggers.py|info|327] [/usr/lib/python3/dist-packages/supervisor/loggers.py|log|345] [/usr/lib/python3/dist-packages/supervisor/loggers.py|emit|227] [/usr/lib/python3/dist-packages/supervisor/loggers.py|doRollover|264])
    return self._cursor()
           ^^^^^^^^^^^^^^
  File "/usr/local/lib/python3.12/site-packages/django/db/backends/base/base.py", line 292, in _cursor
2024-04-28 09:18:15,320 CRIT uncaptured python exception, closing channel <POutputDispatcher at 139975321660752 for <Subprocess at 139975340682896 with name django in state STARTING> (stderr)> (<class 'OSError'>:[Errno 29] Illegal seek [/usr/lib/python3/dist-packages/supervisor/supervisord.py|runforever|218] [/usr/lib/python3/dist-packages/supervisor/dispatchers.py|handle_read_event|276] [/usr/lib/python3/dist-packages/supervisor/dispatchers.py|record_output|210] [/usr/lib/python3/dist-packages/supervisor/dispatchers.py|_log|179] [/usr/lib/python3/dist-packages/supervisor/loggers.py|info|327] [/usr/lib/python3/dist-packages/supervisor/loggers.py|log|345] [/usr/lib/python3/dist-packages/supervisor/loggers.py|emit|227] [/usr/lib/python3/dist-packages/supervisor/loggers.py|doRollover|264])
    self.ensure_connection()
  File "/usr/local/lib/python3.12/site-packages/django/utils/asyncio.py", line 26, in inner
2024-04-28 09:18:15,320 CRIT uncaptured python exception, closing channel <POutputDispatcher at 139975321660752 for <Subprocess at 139975340682896 with name django in state STARTING> (stderr)> (<class 'OSError'>:[Errno 29] Illegal seek [/usr/lib/python3/dist-packages/supervisor/supervisord.py|runforever|218] [/usr/lib/python3/dist-packages/supervisor/dispatchers.py|handle_read_event|276] [/usr/lib/python3/dist-packages/supervisor/dispatchers.py|record_output|210] [/usr/lib/python3/dist-packages/supervisor/dispatchers.py|_log|179] [/usr/lib/python3/dist-packages/supervisor/loggers.py|info|327] [/usr/lib/python3/dist-packages/supervisor/loggers.py|log|345] [/usr/lib/python3/dist-packages/supervisor/loggers.py|emit|227] [/usr/lib/python3/dist-packages/supervisor/loggers.py|doRollover|264])
    return func(*args, **kwargs)
           ^^^^^^^^^^^^^^^^^^^^^
  File "/usr/local/lib/python3.12/site-packages/django/db/backends/base/base.py", line 274, in ensure_connection
2024-04-28 09:18:15,320 CRIT uncaptured python exception, closing channel <POutputDispatcher at 139975321660752 for <Subprocess at 139975340682896 with name django in state STARTING> (stderr)> (<class 'OSError'>:[Errno 29] Illegal seek [/usr/lib/python3/dist-packages/supervisor/supervisord.py|runforever|218] [/usr/lib/python3/dist-packages/supervisor/dispatchers.py|handle_read_event|276] [/usr/lib/python3/dist-packages/supervisor/dispatchers.py|record_output|210] [/usr/lib/python3/dist-packages/supervisor/dispatchers.py|_log|179] [/usr/lib/python3/dist-packages/supervisor/loggers.py|info|327] [/usr/lib/python3/dist-packages/supervisor/loggers.py|log|345] [/usr/lib/python3/dist-packages/supervisor/loggers.py|emit|227] [/usr/lib/python3/dist-packages/supervisor/loggers.py|doRollover|264])
    with self.wrap_database_errors:
  File "/usr/local/lib/python3.12/site-packages/django/db/utils.py", line 91, in __exit__
2024-04-28 09:18:15,320 CRIT uncaptured python exception, closing channel <POutputDispatcher at 139975321660752 for <Subprocess at 139975340682896 with name django in state STARTING> (stderr)> (<class 'OSError'>:[Errno 29] Illegal seek [/usr/lib/python3/dist-packages/supervisor/supervisord.py|runforever|218] [/usr/lib/python3/dist-packages/supervisor/dispatchers.py|handle_read_event|276] [/usr/lib/python3/dist-packages/supervisor/dispatchers.py|record_output|210] [/usr/lib/python3/dist-packages/supervisor/dispatchers.py|_log|179] [/usr/lib/python3/dist-packages/supervisor/loggers.py|info|327] [/usr/lib/python3/dist-packages/supervisor/loggers.py|log|345] [/usr/lib/python3/dist-packages/supervisor/loggers.py|emit|227] [/usr/lib/python3/dist-packages/supervisor/loggers.py|doRollover|264])
    raise dj_exc_value.with_traceback(traceback) from exc_value
  File "/usr/local/lib/python3.12/site-packages/django/db/backends/base/base.py", line 275, in ensure_connection
2024-04-28 09:18:15,320 CRIT uncaptured python exception, closing channel <POutputDispatcher at 139975321660752 for <Subprocess at 139975340682896 with name django in state STARTING> (stderr)> (<class 'OSError'>:[Errno 29] Illegal seek [/usr/lib/python3/dist-packages/supervisor/supervisord.py|runforever|218] [/usr/lib/python3/dist-packages/supervisor/dispatchers.py|handle_read_event|276] [/usr/lib/python3/dist-packages/supervisor/dispatchers.py|record_output|210] [/usr/lib/python3/dist-packages/supervisor/dispatchers.py|_log|179] [/usr/lib/python3/dist-packages/supervisor/loggers.py|info|327] [/usr/lib/python3/dist-packages/supervisor/loggers.py|log|345] [/usr/lib/python3/dist-packages/supervisor/loggers.py|emit|227] [/usr/lib/python3/dist-packages/supervisor/loggers.py|doRollover|264])
    self.connect()
2024-04-28 09:18:15,320 CRIT uncaptured python exception, closing channel <POutputDispatcher at 139975321660752 for <Subprocess at 139975340682896 with name django in state STARTING> (stderr)> (<class 'OSError'>:[Errno 29] Illegal seek [/usr/lib/python3/dist-packages/supervisor/supervisord.py|runforever|218] [/usr/lib/python3/dist-packages/supervisor/dispatchers.py|handle_read_event|276] [/usr/lib/python3/dist-packages/supervisor/dispatchers.py|record_output|210] [/usr/lib/python3/dist-packages/supervisor/dispatchers.py|_log|179] [/usr/lib/python3/dist-packages/supervisor/loggers.py|info|327] [/usr/lib/python3/dist-packages/supervisor/loggers.py|log|345] [/usr/lib/python3/dist-packages/supervisor/loggers.py|emit|227] [/usr/lib/python3/dist-packages/supervisor/loggers.py|doRollover|264])
  File "/usr/local/lib/python3.12/site-packages/django/utils/asyncio.py", line 26, in inner
    return func(*args, **kwargs)
2024-04-28 09:18:15,320 CRIT uncaptured python exception, closing channel <POutputDispatcher at 139975321660752 for <Subprocess at 139975340682896 with name django in state STARTING> (stderr)> (<class 'OSError'>:[Errno 29] Illegal seek [/usr/lib/python3/dist-packages/supervisor/supervisord.py|runforever|218] [/usr/lib/python3/dist-packages/supervisor/dispatchers.py|handle_read_event|276] [/usr/lib/python3/dist-packages/supervisor/dispatchers.py|record_output|210] [/usr/lib/python3/dist-packages/supervisor/dispatchers.py|_log|179] [/usr/lib/python3/dist-packages/supervisor/loggers.py|info|327] [/usr/lib/python3/dist-packages/supervisor/loggers.py|log|345] [/usr/lib/python3/dist-packages/supervisor/loggers.py|emit|227] [/usr/lib/python3/dist-packages/supervisor/loggers.py|doRollover|264])
           ^^^^^^^^^^^^^^^^^^^^^
  File "/usr/local/lib/python3.12/site-packages/django/db/backends/base/base.py", line 256, in connect
2024-04-28 09:18:15,320 CRIT uncaptured python exception, closing channel <POutputDispatcher at 139975321660752 for <Subprocess at 139975340682896 with name django in state STARTING> (stderr)> (<class 'OSError'>:[Errno 29] Illegal seek [/usr/lib/python3/dist-packages/supervisor/supervisord.py|runforever|218] [/usr/lib/python3/dist-packages/supervisor/dispatchers.py|handle_read_event|276] [/usr/lib/python3/dist-packages/supervisor/dispatchers.py|record_output|210] [/usr/lib/python3/dist-packages/supervisor/dispatchers.py|_log|179] [/usr/lib/python3/dist-packages/supervisor/loggers.py|info|327] [/usr/lib/python3/dist-packages/supervisor/loggers.py|log|345] [/usr/lib/python3/dist-packages/supervisor/loggers.py|emit|227] [/usr/lib/python3/dist-packages/supervisor/loggers.py|doRollover|264])
    self.connection = self.get_new_connection(conn_params)
                      ^^^^^^^^^^^^^^^^^^^^^^^^^^^^^^^^^^^^
2024-04-28 09:18:15,320 CRIT uncaptured python exception, closing channel <POutputDispatcher at 139975321660752 for <Subprocess at 139975340682896 with name django in state STARTING> (stderr)> (<class 'OSError'>:[Errno 29] Illegal seek [/usr/lib/python3/dist-packages/supervisor/supervisord.py|runforever|218] [/usr/lib/python3/dist-packages/supervisor/dispatchers.py|handle_read_event|276] [/usr/lib/python3/dist-packages/supervisor/dispatchers.py|record_output|210] [/usr/lib/python3/dist-packages/supervisor/dispatchers.py|_log|179] [/usr/lib/python3/dist-packages/supervisor/loggers.py|info|327] [/usr/lib/python3/dist-packages/supervisor/loggers.py|log|345] [/usr/lib/python3/dist-packages/supervisor/loggers.py|emit|227] [/usr/lib/python3/dist-packages/supervisor/loggers.py|doRollover|264])
  File "/usr/local/lib/python3.12/site-packages/django/utils/asyncio.py", line 26, in inner
    return func(*args, **kwargs)
2024-04-28 09:18:15,321 CRIT uncaptured python exception, closing channel <POutputDispatcher at 139975321660752 for <Subprocess at 139975340682896 with name django in state STARTING> (stderr)> (<class 'OSError'>:[Errno 29] Illegal seek [/usr/lib/python3/dist-packages/supervisor/supervisord.py|runforever|218] [/usr/lib/python3/dist-packages/supervisor/dispatchers.py|handle_read_event|276] [/usr/lib/python3/dist-packages/supervisor/dispatchers.py|record_output|210] [/usr/lib/python3/dist-packages/supervisor/dispatchers.py|_log|179] [/usr/lib/python3/dist-packages/supervisor/loggers.py|info|327] [/usr/lib/python3/dist-packages/supervisor/loggers.py|log|345] [/usr/lib/python3/dist-packages/supervisor/loggers.py|emit|227] [/usr/lib/python3/dist-packages/supervisor/loggers.py|doRollover|264])
           ^^^^^^^^^^^^^^^^^^^^^
  File "/usr/local/lib/python3.12/site-packages/django/db/backends/sqlite3/base.py", line 181, in get_new_connection
2024-04-28 09:18:15,321 CRIT uncaptured python exception, closing channel <POutputDispatcher at 139975321660752 for <Subprocess at 139975340682896 with name django in state STARTING> (stderr)> (<class 'OSError'>:[Errno 29] Illegal seek [/usr/lib/python3/dist-packages/supervisor/supervisord.py|runforever|218] [/usr/lib/python3/dist-packages/supervisor/dispatchers.py|handle_read_event|276] [/usr/lib/python3/dist-packages/supervisor/dispatchers.py|record_output|210] [/usr/lib/python3/dist-packages/supervisor/dispatchers.py|_log|179] [/usr/lib/python3/dist-packages/supervisor/loggers.py|info|327] [/usr/lib/python3/dist-packages/supervisor/loggers.py|log|345] [/usr/lib/python3/dist-packages/supervisor/loggers.py|emit|227] [/usr/lib/python3/dist-packages/supervisor/loggers.py|doRollover|264])
    conn = Database.connect(**conn_params)
           ^^^^^^^^^^^^^^^^^^^^^^^^^^^^^^^
django.db.utils.OperationalError: unable to open database file
2024-04-28 09:18:15,321 CRIT uncaptured python exception, closing channel <POutputDispatcher at 139975321660752 for <Subprocess at 139975340682896 with name django in state STARTING> (stderr)> (<class 'OSError'>:[Errno 29] Illegal seek [/usr/lib/python3/dist-packages/supervisor/supervisord.py|runforever|218] [/usr/lib/python3/dist-packages/supervisor/dispatchers.py|handle_read_event|276] [/usr/lib/python3/dist-packages/supervisor/dispatchers.py|record_output|210] [/usr/lib/python3/dist-packages/supervisor/dispatchers.py|_log|179] [/usr/lib/python3/dist-packages/supervisor/loggers.py|info|327] [/usr/lib/python3/dist-packages/supervisor/loggers.py|log|345] [/usr/lib/python3/dist-packages/supervisor/loggers.py|emit|227] [/usr/lib/python3/dist-packages/supervisor/loggers.py|doRollover|264])
[2024-04-28 09:18:15 +0000] [26] [INFO] Starting gunicorn 22.0.0
2024-04-28 09:18:15,484 CRIT uncaptured python exception, closing channel <POutputDispatcher at 139975321660752 for <Subprocess at 139975340682896 with name django in state STARTING> (stderr)> (<class 'OSError'>:[Errno 29] Illegal seek [/usr/lib/python3/dist-packages/supervisor/supervisord.py|runforever|218] [/usr/lib/python3/dist-packages/supervisor/dispatchers.py|handle_read_event|276] [/usr/lib/python3/dist-packages/supervisor/dispatchers.py|record_output|210] [/usr/lib/python3/dist-packages/supervisor/dispatchers.py|_log|179] [/usr/lib/python3/dist-packages/supervisor/loggers.py|info|327] [/usr/lib/python3/dist-packages/supervisor/loggers.py|log|345] [/usr/lib/python3/dist-packages/supervisor/loggers.py|emit|227] [/usr/lib/python3/dist-packages/supervisor/loggers.py|doRollover|264])
[2024-04-28 09:18:15 +0000] [26] [INFO] Listening at: http://0.0.0.0:8000 (26)
2024-04-28 09:18:15,484 CRIT uncaptured python exception, closing channel <POutputDispatcher at 139975321660752 for <Subprocess at 139975340682896 with name django in state STARTING> (stderr)> (<class 'OSError'>:[Errno 29] Illegal seek [/usr/lib/python3/dist-packages/supervisor/supervisord.py|runforever|218] [/usr/lib/python3/dist-packages/supervisor/dispatchers.py|handle_read_event|276] [/usr/lib/python3/dist-packages/supervisor/dispatchers.py|record_output|210] [/usr/lib/python3/dist-packages/supervisor/dispatchers.py|_log|179] [/usr/lib/python3/dist-packages/supervisor/loggers.py|info|327] [/usr/lib/python3/dist-packages/supervisor/loggers.py|log|345] [/usr/lib/python3/dist-packages/supervisor/loggers.py|emit|227] [/usr/lib/python3/dist-packages/supervisor/loggers.py|doRollover|264])
[2024-04-28 09:18:15 +0000] [26] [INFO] Using worker: sync
2024-04-28 09:18:15,484 CRIT uncaptured python exception, closing channel <POutputDispatcher at 139975321660752 for <Subprocess at 139975340682896 with name django in state STARTING> (stderr)> (<class 'OSError'>:[Errno 29] Illegal seek [/usr/lib/python3/dist-packages/supervisor/supervisord.py|runforever|218] [/usr/lib/python3/dist-packages/supervisor/dispatchers.py|handle_read_event|276] [/usr/lib/python3/dist-packages/supervisor/dispatchers.py|record_output|210] [/usr/lib/python3/dist-packages/supervisor/dispatchers.py|_log|179] [/usr/lib/python3/dist-packages/supervisor/loggers.py|info|327] [/usr/lib/python3/dist-packages/supervisor/loggers.py|log|345] [/usr/lib/python3/dist-packages/supervisor/loggers.py|emit|227] [/usr/lib/python3/dist-packages/supervisor/loggers.py|doRollover|264])
[2024-04-28 09:18:15 +0000] [27] [INFO] Booting worker with pid: 27
2024-04-28 09:18:15,485 CRIT uncaptured python exception, closing channel <POutputDispatcher at 139975321660752 for <Subprocess at 139975340682896 with name django in state STARTING> (stderr)> (<class 'OSError'>:[Errno 29] Illegal seek [/usr/lib/python3/dist-packages/supervisor/supervisord.py|runforever|218] [/usr/lib/python3/dist-packages/supervisor/dispatchers.py|handle_read_event|276] [/usr/lib/python3/dist-packages/supervisor/dispatchers.py|record_output|210] [/usr/lib/python3/dist-packages/supervisor/dispatchers.py|_log|179] [/usr/lib/python3/dist-packages/supervisor/loggers.py|info|327] [/usr/lib/python3/dist-packages/supervisor/loggers.py|log|345] [/usr/lib/python3/dist-packages/supervisor/loggers.py|emit|227] [/usr/lib/python3/dist-packages/supervisor/loggers.py|doRollover|264])
2024-04-28 09:18:16,487 INFO success: django entered RUNNING state, process has stayed up for > than 1 seconds (startsecs)
2024-04-28 09:18:16,487 INFO success: memcached entered RUNNING state, process has stayed up for > than 1 seconds (startsecs)
2024-04-28 09:18:16,487 INFO success: sshd entered RUNNING state, process has stayed up for > than 1 seconds (startsecs)
2024-04-28 09:18:16,487 INFO success: sshd_logwatch entered RUNNING state, process has stayed up for > than 1 seconds (startsecs)
^C2024-04-28 09:21:31,692 WARN received SIGINT indicating exit request
2024-04-28 09:21:31,693 INFO waiting for django, memcached, sshd, sshd_logwatch to die
2024-04-28 09:21:31,695 WARN stopped: sshd_logwatch (terminated by SIGTERM)
2024-04-28 09:21:31,696 INFO stopped: sshd (exit status 0)
Exiting normally
2024-04-28 09:21:31,844 CRIT uncaptured python exception, closing channel <POutputDispatcher at 139975319576976 for <Subprocess at 139975321659856 with name memcached in state STOPPING> (stderr)> (<class 'OSError'>:[Errno 29] Illegal seek [/usr/lib/python3/dist-packages/supervisor/supervisord.py|runforever|218] [/usr/lib/python3/dist-packages/supervisor/dispatchers.py|handle_read_event|276] [/usr/lib/python3/dist-packages/supervisor/dispatchers.py|record_output|210] [/usr/lib/python3/dist-packages/supervisor/dispatchers.py|_log|179] [/usr/lib/python3/dist-packages/supervisor/loggers.py|info|327] [/usr/lib/python3/dist-packages/supervisor/loggers.py|log|345] [/usr/lib/python3/dist-packages/supervisor/loggers.py|emit|227] [/usr/lib/python3/dist-packages/supervisor/loggers.py|doRollover|264])
2024-04-28 09:21:31,844 INFO stopped: memcached (exit status 0)
2024-04-28 09:21:32,844 WARN stopped: django (terminated by SIGTERM)
task: Signal received: "interrupt"
